Workbook

Sheet 1. Capa
B2: DA ENGENHARIA AO CASO DE INVESTIMENTO
B3: Planta de doce de leite · 2024–2033 · modelo financeiro em padrão FP&A
B5: Projeto de conclusão de Engenharia de Alimentos (UNICAMP) relido como caso de investimento. A planilha original tem 27 abas de engenharia — balanço de massa, mapa de ocupação, APPCC — e nenhuma DRE. Este modelo não refaz a engenharia: consome os resultados dela como premissa e constrói em cima a camada que um comitê de investimento espera ver.
B9: RESULTADO — CENÁRIO ATIVO | D9: ='2. Inputs'!D5
B10: VPL @ WACC | D10: ='6. Valuation'!C18
B11: TIR | D11: ='6. Valuation'!C21
B12: WACC | D12: ='2. Inputs'!C81
B13: Payback descontado | D13: ='6. Valuation'!C24
B14: CAPEX no ano 0 | D14: ='2. Inputs'!C53
B15: EBITDA — ano 1 | D15: ='4. DRE'!D39
B16: Margem EBITDA — ano 1 | D16: ='4. DRE'!D40
B17: EBITDA — ano 10 | D17: ='4. DRE'!M39
B18: Margem EBITDA — ano 10 | D18: ='4. DRE'!M40
B19: Margem de segurança sobre o ponto de equilíbrio — ano 1 | D19: ='7. Cenarios e Sensibilidade'!D60
B21: CHECKS DE AMARRAÇÃO | D21: ='10. Checks'!C4
B23: O QUE ESTE MODELO CORRIGE
B24: Gap | C24: O que havia na origem | D24: O que este modelo faz | E24: Onde
B25: 1. DRE em formato FP&A | C25: Resultado espalhado entre 3 abas. Nenhuma linha de EBITDA, EBIT ou margem. | D25: DRE completa com margem em cada linha e memória por unidade. | G25: 4. DRE
B26: 2. Premissa dentro de fórmula | C26: Markup =0,18+0,0065+0,03+0,03+0,25 numa célula. CTU e volume digitados à mão. | D26: Toda premissa numa célula identificada, com fonte, na aba de inputs. | G26: 2. Inputs
B27: 3. Depreciação errada | C27: Anotado pelo próprio autor. Quatro defeitos: base incompleta, vida útil ignorada, reinvestimento sem depreciação, base de volume inconsistente. | D27: Registro de ativos por classe e vida útil, cronograma linear, antes e depois documentado. | G27: 3. Depreciacao
B28: 4. Taxa de desconto | C28: Selic de 12,25%, "vigente em outubro de 2020", sem prêmio de risco. | D28: WACC construído (CAPM), com o impacto no VPL isolado numa ponte de duas pontas. | G28: 6. Valuation
B29: 5. Cenários e sensibilidade | C29: Não existiam. | D29: Três cenários por seletor único, tornado de cinco alavancas, sensibilidade ao custo de capital e tabela WACC x g. | G29: 7. Cenarios
B30: 6. Checks, capa e sumário | C30: Nenhuma célula de verificação na planilha inteira. | D30: 19 checks de amarração e esta capa. | G30: 10. Checks
B31: 7. Ponte de variância de EBITDA | C31: Não havia EBITDA para decompor. | D31: Ponte volume x preço x mix x custo, ano a ano, fechando exatamente, com comentário de gestor. | G31: 9. Ponte EBITDA
B32: 8. Ponto de equilíbrio | C32: Calculado sobre um CTU diferente do usado na DRE, sem leitura de negócio. | D32: PE contábil e de caixa, margem de segurança, alavancagem operacional e o que isso significa. | G32: 7. Cenarios
B34: ACHADOS QUE NÃO ESTAVAM NA LISTA
B35: • O reinvestimento de 2028 estava R$ 5,6 mi inflado por duas referências erradas: 25 notebooks multiplicados pelo preço do tanque de leite, e uma soma elevada ao quadrado no laboratório.
B36: • O CUB (R$ 2.163,98 por m²) entrava somado ao investimento como se fosse um valor de obra.
B37: • A empilhadeira de 2030 era contada duas vezes dentro do mesmo SOMA.
B38: • A rotação do leite no crédito de fornecedores do ano 2 estava 260 em vez de 12 — copiada da linha de estoque.
B39: • A planilha vendia ~10% mais unidades do que produzia, todo ano, sem estoque.
B40: • A parcela de 3% que estava dentro do markup nunca virou despesa: era margem escondida.
B41: • No modo de precificação da origem (custo + markup), custo mais alto gera VPL mais alto. O modelo premiava ineficiência. Há um seletor na aba 2. Inputs para testar preço de mercado fixo.
B43: ÍNDICE
B44: 2. Inputs | C44: Todas as premissas, com fonte. Seletor de cenário em C5 e modo de precificação.
B45: 3. Depreciacao | C45: Registro de ativos, cronograma e o diagnóstico dos quatro defeitos da origem.
B46: 4. DRE | C46: Resultado em formato FP&A, com margem em cada linha.
B47: 5. Fluxo de Caixa | C47: Capital de giro reconstruído e fluxo de caixa livre.
B48: 6. Valuation | C48: WACC, VPL, TIR, payback, valor terminal e a ponte de VPL contra a origem.
B49: 7. Cenarios e Sensibilidade | C49: Três cenários, tornado, sensibilidade e ponto de equilíbrio.
...

Sheet 2. Inputs
A1: INPUTS E PREMISSAS
A2: Business case — planta de doce de leite | Toda premissa do modelo vive nesta aba. Nenhum número entra em fórmula fora daqui.
A4: Convenção de cor: | C4: AZUL = input | E4: PRETO = fórmula | G4: VERDE = link de outra aba | I4: AMARELO = a confirmar
A5: CENÁRIO ATIVO (1 = Pessimista · 2 = Base · 3 = Otimista) | C5: 2 | D5: =INDEX($C$93:$E$93,1,$C$5) | F5: <- nome do cenário lido da tabela de alavancas (bloco J)
A7: Ano | C7: 0 | D7: 1 | E7: 2 | F7: 3 | G7: 4 | H7: 5 | I7: 6 | J7: 7 | K7: 8 | L7: 9 | M7: 10 | O7: Fonte / observação
A8: Exercício | C8: 2023 | D8: 2024 | E8: 2025 | F8: 2026 | G8: 2027 | H8: 2028 | I8: 2029 | J8: 2030 | K8: 2031 | L8: 2032 | M8: 2033
A10: A. VOLUME
A11: Unidades produzidas — origem | B11: un/ano | D11: 1244035 | E11: 1375555 | F11: 1520979 | G11: 1681776 | H11: 1893740 | I11: 2056155 | J11: 2273468 | K11: 2513625 | L11: 2785395 | M11: 3079476 | O11: Origem: '7. Massas iniciais, ritmo de tr'!R122:R131 (balanço de massa). Não recalculado.
A12: Unidades vendidas — origem (referência) | B12: un/ano | D12: 1368200 | E12: 1375315 | F12: 1520713 | G12: 1681483 | H12: 1859250 | I12: 2093581 | J12: 2273136 | K12: 2513381 | L12: 2778882 | M12: 3079331 | O12: Origem: '3. Projeção de produção'!G23:G32, digitadas à mão. Divergem ~10% das produzidas. Ver D-01 em gaps-e-decisoes.
A13: Δ volume do cenário | B13: % | C13: =IF(C$8="2023","",INDEX($C$88:$E$88,1,$C$5)) | D13: =IF(D$8="2023","",INDEX($C$88:$E$88,1,$C$5)) | E13: =IF(E$8="2023","",INDEX($C$88:$E$88,1,$C$5)) | F13: =IF(F$8="2023","",INDEX($C$88:$E$88,1,$C$5)) | G13: =IF(G$8="2023","",INDEX($C$88:$E$88,1,$C$5)) | H13: =IF(H$8="2023","",INDEX($C$88:$E$88,1,$C$5)) | I13: =IF(I$8="2023","",INDEX($C$88:$E$88,1,$C$5)) | J13: =IF(J$8="2023","",INDEX($C$88:$E$88,1,$C$5)) | ... M13: =IF(M$8="2023","",INDEX($C$88:$E$88,1,$C$5)) | O13: Alavanca de cenário — bloco J.
A14: VOLUME DO MODELO | B14: un/ano | C14: =IF(C$8="2023","",C11*(1+C13)) | D14: =IF(D$8="2023","",D11*(1+D13)) | E14: =IF(E$8="2023","",E11*(1+E13)) | F14: =IF(F$8="2023","",F11*(1+F13)) | G14: =IF(G$8="2023","",G11*(1+G13)) | H14: =IF(H$8="2023","",H11*(1+H13)) | I14: =IF(I$8="2023","",I11*(1+I13)) | J14: =IF(J$8="2023","",J11*(1+J13)) | ... M14: =IF(M$8="2023","",M11*(1+M13)) | O14: Volume = produzido. Vender mais do que se produz, sem estoque, não se sustenta (D-01).
A15: Crescimento do volume | B15: % a.a. | E15: =IFERROR(E14/D14-1,"") | F15: =IFERROR(F14/E14-1,"") | G15: =IFERROR(G14/F14-1,"") | H15: =IFERROR(H14/G14-1,"") | I15: =IFERROR(I14/H14-1,"") | J15: =IFERROR(J14/I14-1,"") | K15: =IFERROR(K14/J14-1,"") | L15: =IFERROR(L14/K14-1,"") | M15: =IFERROR(M14/L14-1,"")
A17: B. MIX REGIONAL E FRETE
A18: Participação — Sudeste (alavanca) | B18: % | C18: =IF(C$8="2023","",INDEX($C$92:$E$92,1,$C$5)) | D18: =IF(D$8="2023","",INDEX($C$92:$E$92,1,$C$5)) | E18: =IF(E$8="2023","",INDEX($C$92:$E$92,1,$C$5)) | F18: =IF(F$8="2023","",INDEX($C$92:$E$92,1,$C$5)) | G18: =IF(G$8="2023","",INDEX($C$92:$E$92,1,$C$5)) | H18: =IF(H$8="2023","",INDEX($C$92:$E$92,1,$C$5)) | I18: =IF(I$8="2023","",INDEX($C$92:$E$92,1,$C$5)) | J18: =IF(J$8="2023","",INDEX($C$92:$E$92,1,$C$5)) | ... M18: =IF(M$8="2023","",INDEX($C$92:$E$92,1,$C$5)) | O18: Origem: 20. Custos Unitários!D96. É a alavanca de mix do cenário.
A19: Participação — Sul | B19: % | C19: =IF(C$8="2023","",$C$96/$C$100*(1-C18)) | D19: =IF(D$8="2023","",$C$96/$C$100*(1-D18)) | E19: =IF(E$8="2023","",$C$96/$C$100*(1-E18)) | F19: =IF(F$8="2023","",$C$96/$C$100*(1-F18)) | G19: =IF(G$8="2023","",$C$96/$C$100*(1-G18)) | H19: =IF(H$8="2023","",$C$96/$C$100*(1-H18)) | I19: =IF(I$8="2023","",$C$96/$C$100*(1-I18)) | J19: =IF(J$8="2023","",$C$96/$C$100*(1-J18)) | ... M19: =IF(M$8="2023","",$C$96/$C$100*(1-M18)) | O19: Origem: 20. Custos Unitários!C96. Redistribuída proporcionalmente quando o Sudeste muda.
A20: Participação — Nordeste | B20: % | C20: =IF(C$8="2023","",$C$97/$C$100*(1-C18)) | D20: =IF(D$8="2023","",$C$97/$C$100*(1-D18)) | E20: =IF(E$8="2023","",$C$97/$C$100*(1-E18)) | F20: =IF(F$8="2023","",$C$97/$C$100*(1-F18)) | G20: =IF(G$8="2023","",$C$97/$C$100*(1-G18)) | H20: =IF(H$8="2023","",$C$97/$C$100*(1-H18)) | I20: =IF(I$8="2023","",$C$97/$C$100*(1-I18)) | J20: =IF(J$8="2023","",$C$97/$C$100*(1-J18)) | ... M20: =IF(M$8="2023","",$C$97/$C$100*(1-M18)) | O20: Origem: 20. Custos Unitários!E96. Redistribuída proporcionalmente quando o Sudeste muda.
A21: Participação — Norte | B21: % | C21: =IF(C$8="2023","",$C$98/$C$100*(1-C18)) | D21: =IF(D$8="2023","",$C$98/$C$100*(1-D18)) | E21: =IF(E$8="2023","",$C$98/$C$100*(1-E18)) | F21: =IF(F$8="2023","",$C$98/$C$100*(1-F18)) | G21: =IF(G$8="2023","",$C$98/$C$100*(1-G18)) | H21: =IF(H$8="2023","",$C$98/$C$100*(1-H18)) | I21: =IF(I$8="2023","",$C$98/$C$100*(1-I18)) | J21: =IF(J$8="2023","",$C$98/$C$100*(1-J18)) | ... M21: =IF(M$8="2023","",$C$98/$C$100*(1-M18)) | O21: Origem: 20. Custos Unitários!F96. Redistribuída proporcionalmente quando o Sudeste muda.
A22: Participação — Centro-Oeste | B22: % | C22: =IF(C$8="2023","",$C$99/$C$100*(1-C18)) | D22: =IF(D$8="2023","",$C$99/$C$100*(1-D18)) | E22: =IF(E$8="2023","",$C$99/$C$100*(1-E18)) | F22: =IF(F$8="2023","",$C$99/$C$100*(1-F18)) | G22: =IF(G$8="2023","",$C$99/$C$100*(1-G18)) | H22: =IF(H$8="2023","",$C$99/$C$100*(1-H18)) | I22: =IF(I$8="2023","",$C$99/$C$100*(1-I18)) | J22: =IF(J$8="2023","",$C$99/$C$100*(1-J18)) | ... M22: =IF(M$8="2023","",$C$99/$C$100*(1-M18)) | O22: Origem: 20. Custos Unitários!G96. Redistribuída proporcionalmente quando o Sudeste muda.
A23: Soma das participações | B23: % | C23: =IF(C$8="2023","",SUM(C18:C22)) | D23: =IF(D$8="2023","",SUM(D18:D22)) | E23: =IF(E$8="2023","",SUM(E18:E22)) | F23: =IF(F$8="2023","",SUM(F18:F22)) | G23: =IF(G$8="2023","",SUM(G18:G22)) | H23: =IF(H$8="2023","",SUM(H18:H22)) | I23: =IF(I$8="2023","",SUM(I18:I22)) | J23: =IF(J$8="2023","",SUM(J18:J22)) | ... M23: =IF(M$8="2023","",SUM(M18:M22))
A24: Frete unitário — Sudeste | B24: R$/un | D24: 0.040654 | E24: 0.040654 | F24: 0.040654 | G24: 0.040654 | H24: 0.040654 | I24: 0.040654 | J24: 0.040654 | K24: 0.040654 | L24: 0.040654 | M24: 0.040654 | O24: Derivado de 20. Custos Unitários!C114:G123 / share / unidades. Constante por unidade em todo o horizonte.
A25: Frete unitário — Sul | B25: R$/un | D25: 0.097814 | E25: 0.097814 | F25: 0.097814 | G25: 0.097814 | H25: 0.097814 | I25: 0.097814 | J25: 0.097814 | K25: 0.097814 | L25: 0.097814 | M25: 0.097814 | O25: Derivado de 20. Custos Unitários!C114:G123 / share / unidades. Constante por unidade em todo o horizonte.
A26: Frete unitário — Nordeste | B26: R$/un | D26: 0.198798 | E26: 0.198798 | F26: 0.198798 | G26: 0.198798 | H26: 0.198798 | I26: 0.198798 | J26: 0.198798 | K26: 0.198798 | L26: 0.198798 | M26: 0.198798 | O26: Derivado de 20. Custos Unitários!C114:G123 / share / unidades. Constante por unidade em todo o horizonte.
A27: Frete unitário — Norte | B27: R$/un | D27: 0.299174 | E27: 0.299174 | F27: 0.299174 | G27: 0.299174 | H27: 0.299174 | I27: 0.299174 | J27: 0.299174 | K27: 0.299174 | L27: 0.299174 | M27: 0.299174 | O27: Derivado de 20. Custos Unitários!C114:G123 / share / unidades. Constante por unidade em todo o horizonte.
A28: Frete unitário — Centro-Oeste | B28: R$/un | D28: 0.121031 | E28: 0.121031 | F28: 0.121031 | G28: 0.121031 | H28: 0.121031 | I28: 0.121031 | J28: 0.121031 | K28: 0.121031 | L28: 0.121031 | M28: 0.121031 | O28: Derivado de 20. Custos Unitários!C114:G123 / share / unidades. Constante por unidade em todo o horizonte.
A29: FRETE UNITÁRIO PONDERADO | B29: R$/un | C29: =IF(C$8="2023","",SUMPRODUCT(C18:C22,C24:C28)) | D29: =IF(D$8="2023","",SUMPRODUCT(D18:D22,D24:D28)) | E29: =IF(E$8="2023","",SUMPRODUCT(E18:E22,E24:E28)) | F29: =IF(F$8="2023","",SUMPRODUCT(F18:F22,F24:F28)) | G29: =IF(G$8="2023","",SUMPRODUCT(G18:G22,G24:G28)) | H29: =IF(H$8="2023","",SUMPRODUCT(H18:H22,H24:H28)) | I29: =IF(I$8="2023","",SUMPRODUCT(I18:I22,I24:I28)) | J29: =IF(J$8="2023","",SUMPRODUCT(J18:J22,J24:J28)) | ... M29: =IF(M$8="2023","",SUMPRODUCT(M18:M22,M24:M28)) | O29: Cálculo: SOMARPRODUTO(participações; fretes unitários).
A31: C. PREÇO E MARKUP
A32: ICMS | B32: % | D32: 0.18 | E32: 0.18 | F32: 0.18 | G32: 0.18 | H32: 0.18 | I32: 0.18 | J32: 0.18 | K32: 0.18 | L32: 0.18 | M32: 0.18 | O32: Origem: 21. PVU!I3, alíquota que estava dentro da fórmula.
A33: PIS | B33: % | D33: 0.0065 | E33: 0.0065 | F33: 0.0065 | G33: 0.0065 | H33: 0.0065 | I33: 0.0065 | J33: 0.0065 | K33: 0.0065 | L33: 0.0065 | M33: 0.0065 | O33: Origem: 21. PVU!I3.
A34: COFINS | B34: % | D34: 0.03 | E34: 0.03 | F34: 0.03 | G34: 0.03 | H34: 0.03 | I34: 0.03 | J34: 0.03 | K34: 0.03 | L34: 0.03 | M34: 0.03 | O34: Origem: 21. PVU!I3.
A35: Comissão e outros sobre venda | B35: % | D35: 0.03 | E35: 0.03 | F35: 0.03 | G35: 0.03 | H35: 0.03 | I35: 0.03 | J35: 0.03 | K35: 0.03 | L35: 0.03 | M35: 0.03 | O35: (confirmar) — a parcela 0,03 do markup da origem nunca foi identificada nem cobrada como despesa. Aqui vira linha de custo. Zerar se não existir.
A36: Margem-alvo sobre preço | B36: % | D36: 0.25 | E36: 0.27 | F36: 0.29 | G36: 0.31 | H36: 0.33 | I36: 0.35 | J36: 0.37 | K36: 0.39 | L36: 0.41 | M36: 0.43 | O36: (confirmar) — origem: 21. PVU!B3:B12, sobe 2 p.p. ao ano até 43% sem justificativa de mercado.
A37: Δ margem-alvo do cenário | B37: p.p. | C37: =IF(C$8="2023","",INDEX($C$89:$E$89,1,$C$5)) | D37: =IF(D$8="2023","",INDEX($C$89:$E$89,1,$C$5)) | E37: =IF(E$8="2023","",INDEX($C$89:$E$89,1,$C$5)) | F37: =IF(F$8="2023","",INDEX($C$89:$E$89,1,$C$5)) | G37: =IF(G$8="2023","",INDEX($C$89:$E$89,1,$C$5)) | H37: =IF(H$8="2023","",INDEX($C$89:$E$89,1,$C$5)) | I37: =IF(I$8="2023","",INDEX($C$89:$E$89,1,$C$5)) | J37: =IF(J$8="2023","",INDEX($C$89:$E$89,1,$C$5)) | ... M37: =IF(M$8="2023","",INDEX($C$89:$E$89,1,$C$5)) | O37: Alavanca de cenário — bloco J.
A38: MODO DE PRECIFICAÇÃO | B38: 1 ou 2 | C38: 1 | O38: 1 = custo + markup (a lógica da origem) · 2 = preço de mercado fixo. No modo 1 o preço sobe junto com o custo: o modelo PREMIA ineficiência. Ver D-07 em gaps-e-decisoes.
A39: Preço de mercado | B39: R$/un | D39: 30.4717 | E39: 30.832 | F39: 31.341 | G39: 32.0037 | H39: 32.9725 | I39: 34.0046 | J39: 35.1081 | K39: 36.6072 | L39: 38.0728 | M39: 39.7606 | O39: (confirmar) — semeado com o preço que o modo 1 gera no cenário Base. Substituir por preço observado de doce de leite 600 g quando houver fonte.
A40: MARKUP TOTAL | B40: % | C40: =IF(C$8="2023","",C32+C33+C34+C35+C36+C37) | D40: =IF(D$8="2023","",D32+D33+D34+D35+D36+D37) | E40: =IF(E$8="2023","",E32+E33+E34+E35+E36+E37) | F40: =IF(F$8="2023","",F32+F33+F34+F35+F36+F37) | G40: =IF(G$8="2023","",G32+G33+G34+G35+G36+G37) | H40: =IF(H$8="2023","",H32+H33+H34+H35+H36+H37) | I40: =IF(I$8="2023","",I32+I33+I34+I35+I36+I37) | J40: =IF(J$8="2023","",J32+J33+J34+J35+J36+J37) | ... M40: =IF(M$8="2023","",M32+M33+M34+M35+M36+M37) | O40: Cálculo: ICMS + PIS + COFINS + comissão + margem-alvo. Era =0,18+0,0065+0,03+0,03+0,25 numa célula só.
A42: D. CUSTOS OPERACIONAIS
A43: Custo variável unitário (ex-frete) | B43: R$/un | D43: 11.1316 | E43: 11.0931 | F43: 11.0712 | G43: 11.0489 | H43: 11.0951 | I43: 11.0763 | J43: 11.0478 | K43: 11.104 | L43: 11.0842 | M43: 11.0533 | O43: Derivado: (20. Custos Unitários!K − I) / unidades produzidas. MP, embalagens, insumos, energia, água, EPI, limpeza.
A44: Δ custo variável unitário do cenário | B44: % | C44: =IF(C$8="2023","",INDEX($C$90:$E$90,1,$C$5)) | D44: =IF(D$8="2023","",INDEX($C$90:$E$90,1,$C$5)) | E44: =IF(E$8="2023","",INDEX($C$90:$E$90,1,$C$5)) | F44: =IF(F$8="2023","",INDEX($C$90:$E$90,1,$C$5)) | G44: =IF(G$8="2023","",INDEX($C$90:$E$90,1,$C$5)) | H44: =IF(H$8="2023","",INDEX($C$90:$E$90,1,$C$5)) | I44: =IF(I$8="2023","",INDEX($C$90:$E$90,1,$C$5)) | J44: =IF(J$8="2023","",INDEX($C$90:$E$90,1,$C$5)) | ... M44: =IF(M$8="2023","",INDEX($C$90:$E$90,1,$C$5)) | O44: Alavanca de cenário — bloco J.
A45: CUSTO VARIÁVEL UNITÁRIO DO MODELO | B45: R$/un | C45: =IF(C$8="2023","",C43*(1+C44)) | D45: =IF(D$8="2023","",D43*(1+D44)) | E45: =IF(E$8="2023","",E43*(1+E44)) | F45: =IF(F$8="2023","",F43*(1+F44)) | G45: =IF(G$8="2023","",G43*(1+G44)) | H45: =IF(H$8="2023","",H43*(1+H44)) | I45: =IF(I$8="2023","",I43*(1+I44)) | J45: =IF(J$8="2023","",J43*(1+J44)) | ... M45: =IF(M$8="2023","",M43*(1+M44))
A46: Custo fixo de estrutura (caixa) | B46: R$/ano | D46: 1792483.8 | E46: 1792450 | F46: 1792450 | G46: 1792450 | H46: 1886512.5 | I46: 1886548 | J46: 1886548 | K46: 1886548 | L46: 1886583.5 | M46: 1886512.5 | O46: Origem: 20. Custos Unitários, colunas L+M+N+O+Q (mat. administrativo, higiene, folha, encargos, laboratório).
...

Sheet 3. Depreciacao
A1: DEPRECIAÇÃO — DIAGNÓSTICO E CORREÇÃO
A2: O autor anotou "Depreciacao esta errada" em 22.2 Fluxo de Caixa!C5. São quatro defeitos distintos. Esta aba mostra o antes e o depois.
A7: Ano | C7: 0 | D7: 1 | E7: 2 | F7: 3 | G7: 4 | H7: 5 | I7: 6 | J7: 7 | K7: 8 | L7: 9 | M7: 10 | O7: Fonte / observação
A8: Exercício | C8: 2023 | D8: 2024 | E8: 2025 | F8: 2026 | G8: 2027 | H8: 2028 | I8: 2029 | J8: 2030 | K8: 2031 | L8: 2032 | M8: 2033
A10: A. REGISTRO DE ATIVOS (base corrigida)
A11: Ativo | B11: Classe | C11: Ano de entrada | D11: Valor (R$) | E11: Vida útil (anos) | F11: Taxa anual | G11: Depreciação anual (R$)
A12: Construção civil | B12: Edificações | C12: 0 | D12: 12472315 | E12: 25 | F12: =1/E12 | G12: =D12/E12 | O12: Origem: 'Demanda...'!AM5 = CUB x 4.803 m2 x 1,20.
A13: Equipamentos e instalações — ano 0 | B13: Equipamentos | C13: 0 | D13: 3562305.5 | E13: 10 | F13: =1/E13 | G13: =D13/E13 | O13: Equip. de processo + auxiliares + itens de laboratório e pias, TODOS com o acréscimo de 15%. A origem pegou os itens de laboratório antes do acréscimo e esqueceu bancada e armário (D1).
A14: Informática e móveis — ano 0 | B14: Informática/móveis | C14: 0 | D14: 167205.52 | E14: 5 | F14: =1/E14 | G14: =D14/E14 | O14: Equip. administrativos + impressora de laboratório + armários de vestiário, com o acréscimo de 15%.
A15: Reator encamisado (2027) | B15: Equipamentos | C15: 4 | D15: 161000 | E15: 10 | F15: =1/E15 | G15: =D15/E15 | O15: Origem: 'Demanda...'!AE10. Reinvestimento que nunca entrou na base (D3).
A16: Refratômetro e phmetro (2028) | B16: Equipamentos | C16: 5 | D16: 2388.55 | E16: 10 | F16: =1/E16 | G16: =D16/E16 | O16: Renovação de laboratório.
A17: Renovação de informática e móveis (2028) | B17: Informática/móveis | C17: 5 | D17: 140730.1 | E17: 5 | F17: =1/E17 | G17: =D17/E17 | O17: 25 notebooks, 30 cadeiras, 5 impressoras. É a renovação de 5 anos dos ativos de vida curta — e confirma que os R$ 5,7 mi da origem eram erro de fórmula (A-01).
A18: Reator e empilhadeira (2030) | B18: Equipamentos | C18: 7 | D18: 289800 | E18: 10 | F18: =1/E18 | G18: =D18/E18 | O18: Origem: 'Demanda...'!AH10+AH17. A origem somava a empilhadeira duas vezes (A-01).
A19: Subtotal depreciável | D19: =SUM(D12:D18)
A20: Terreno (não depreciável) | D20: 908611.9 | O20: Origem: 'Demanda...'!AM6. Terreno não deprecia — a origem acertou aqui.
A21: TOTAL ATIVO IMOBILIZADO | D21: =D19+D20
A23: B. CRONOGRAMA DE DEPRECIAÇÃO (linear, início no ano seguinte à entrada)
A24: Construção civil | C24: =IF(AND(0>$C$12,0<=$C$12+$E$12),$D$12/$E$12,0) | D24: =IF(AND(1>$C$12,1<=$C$12+$E$12),$D$12/$E$12,0) | E24: =IF(AND(2>$C$12,2<=$C$12+$E$12),$D$12/$E$12,0) | F24: =IF(AND(3>$C$12,3<=$C$12+$E$12),$D$12/$E$12,0) | G24: =IF(AND(4>$C$12,4<=$C$12+$E$12),$D$12/$E$12,0) | H24: =IF(AND(5>$C$12,5<=$C$12+$E$12),$D$12/$E$12,0) | I24: =IF(AND(6>$C$12,6<=$C$12+$E$12),$D$12/$E$12,0) | J24: =IF(AND(7>$C$12,7<=$C$12+$E$12),$D$12/$E$12,0) | K24: =IF(AND(8>$C$12,8<=$C$12+$E$12),$D$12/$E$12,0) | L24: =IF(AND(9>$C$12,9<=$C$12+$E$12),$D$12/$E$12,0) | M24: =IF(AND(10>$C$12,10<=$C$12+$E$12),$D$12/$E$12,0)
A25: Equipamentos e instalações — ano 0 | C25: =IF(AND(0>$C$13,0<=$C$13+$E$13),$D$13/$E$13,0) | D25: =IF(AND(1>$C$13,1<=$C$13+$E$13),$D$13/$E$13,0) | E25: =IF(AND(2>$C$13,2<=$C$13+$E$13),$D$13/$E$13,0) | F25: =IF(AND(3>$C$13,3<=$C$13+$E$13),$D$13/$E$13,0) | G25: =IF(AND(4>$C$13,4<=$C$13+$E$13),$D$13/$E$13,0) | H25: =IF(AND(5>$C$13,5<=$C$13+$E$13),$D$13/$E$13,0) | I25: =IF(AND(6>$C$13,6<=$C$13+$E$13),$D$13/$E$13,0) | J25: =IF(AND(7>$C$13,7<=$C$13+$E$13),$D$13/$E$13,0) | K25: =IF(AND(8>$C$13,8<=$C$13+$E$13),$D$13/$E$13,0) | L25: =IF(AND(9>$C$13,9<=$C$13+$E$13),$D$13/$E$13,0) | M25: =IF(AND(10>$C$13,10<=$C$13+$E$13),$D$13/$E$13,0)
A26: Informática e móveis — ano 0 | C26: =IF(AND(0>$C$14,0<=$C$14+$E$14),$D$14/$E$14,0) | D26: =IF(AND(1>$C$14,1<=$C$14+$E$14),$D$14/$E$14,0) | E26: =IF(AND(2>$C$14,2<=$C$14+$E$14),$D$14/$E$14,0) | F26: =IF(AND(3>$C$14,3<=$C$14+$E$14),$D$14/$E$14,0) | G26: =IF(AND(4>$C$14,4<=$C$14+$E$14),$D$14/$E$14,0) | H26: =IF(AND(5>$C$14,5<=$C$14+$E$14),$D$14/$E$14,0) | I26: =IF(AND(6>$C$14,6<=$C$14+$E$14),$D$14/$E$14,0) | J26: =IF(AND(7>$C$14,7<=$C$14+$E$14),$D$14/$E$14,0) | K26: =IF(AND(8>$C$14,8<=$C$14+$E$14),$D$14/$E$14,0) | L26: =IF(AND(9>$C$14,9<=$C$14+$E$14),$D$14/$E$14,0) | M26: =IF(AND(10>$C$14,10<=$C$14+$E$14),$D$14/$E$14,0)
A27: Reator encamisado (2027) | C27: =IF(AND(0>$C$15,0<=$C$15+$E$15),$D$15/$E$15,0) | D27: =IF(AND(1>$C$15,1<=$C$15+$E$15),$D$15/$E$15,0) | E27: =IF(AND(2>$C$15,2<=$C$15+$E$15),$D$15/$E$15,0) | F27: =IF(AND(3>$C$15,3<=$C$15+$E$15),$D$15/$E$15,0) | G27: =IF(AND(4>$C$15,4<=$C$15+$E$15),$D$15/$E$15,0) | H27: =IF(AND(5>$C$15,5<=$C$15+$E$15),$D$15/$E$15,0) | I27: =IF(AND(6>$C$15,6<=$C$15+$E$15),$D$15/$E$15,0) | J27: =IF(AND(7>$C$15,7<=$C$15+$E$15),$D$15/$E$15,0) | K27: =IF(AND(8>$C$15,8<=$C$15+$E$15),$D$15/$E$15,0) | L27: =IF(AND(9>$C$15,9<=$C$15+$E$15),$D$15/$E$15,0) | M27: =IF(AND(10>$C$15,10<=$C$15+$E$15),$D$15/$E$15,0)
A28: Refratômetro e phmetro (2028) | C28: =IF(AND(0>$C$16,0<=$C$16+$E$16),$D$16/$E$16,0) | D28: =IF(AND(1>$C$16,1<=$C$16+$E$16),$D$16/$E$16,0) | E28: =IF(AND(2>$C$16,2<=$C$16+$E$16),$D$16/$E$16,0) | F28: =IF(AND(3>$C$16,3<=$C$16+$E$16),$D$16/$E$16,0) | G28: =IF(AND(4>$C$16,4<=$C$16+$E$16),$D$16/$E$16,0) | H28: =IF(AND(5>$C$16,5<=$C$16+$E$16),$D$16/$E$16,0) | I28: =IF(AND(6>$C$16,6<=$C$16+$E$16),$D$16/$E$16,0) | J28: =IF(AND(7>$C$16,7<=$C$16+$E$16),$D$16/$E$16,0) | K28: =IF(AND(8>$C$16,8<=$C$16+$E$16),$D$16/$E$16,0) | L28: =IF(AND(9>$C$16,9<=$C$16+$E$16),$D$16/$E$16,0) | M28: =IF(AND(10>$C$16,10<=$C$16+$E$16),$D$16/$E$16,0)
A29: Renovação de informática e móveis (2028) | C29: =IF(AND(0>$C$17,0<=$C$17+$E$17),$D$17/$E$17,0) | D29: =IF(AND(1>$C$17,1<=$C$17+$E$17),$D$17/$E$17,0) | E29: =IF(AND(2>$C$17,2<=$C$17+$E$17),$D$17/$E$17,0) | F29: =IF(AND(3>$C$17,3<=$C$17+$E$17),$D$17/$E$17,0) | G29: =IF(AND(4>$C$17,4<=$C$17+$E$17),$D$17/$E$17,0) | H29: =IF(AND(5>$C$17,5<=$C$17+$E$17),$D$17/$E$17,0) | I29: =IF(AND(6>$C$17,6<=$C$17+$E$17),$D$17/$E$17,0) | J29: =IF(AND(7>$C$17,7<=$C$17+$E$17),$D$17/$E$17,0) | K29: =IF(AND(8>$C$17,8<=$C$17+$E$17),$D$17/$E$17,0) | L29: =IF(AND(9>$C$17,9<=$C$17+$E$17),$D$17/$E$17,0) | M29: =IF(AND(10>$C$17,10<=$C$17+$E$17),$D$17/$E$17,0)
A30: Reator e empilhadeira (2030) | C30: =IF(AND(0>$C$18,0<=$C$18+$E$18),$D$18/$E$18,0) | D30: =IF(AND(1>$C$18,1<=$C$18+$E$18),$D$18/$E$18,0) | E30: =IF(AND(2>$C$18,2<=$C$18+$E$18),$D$18/$E$18,0) | F30: =IF(AND(3>$C$18,3<=$C$18+$E$18),$D$18/$E$18,0) | G30: =IF(AND(4>$C$18,4<=$C$18+$E$18),$D$18/$E$18,0) | H30: =IF(AND(5>$C$18,5<=$C$18+$E$18),$D$18/$E$18,0) | I30: =IF(AND(6>$C$18,6<=$C$18+$E$18),$D$18/$E$18,0) | J30: =IF(AND(7>$C$18,7<=$C$18+$E$18),$D$18/$E$18,0) | K30: =IF(AND(8>$C$18,8<=$C$18+$E$18),$D$18/$E$18,0) | L30: =IF(AND(9>$C$18,9<=$C$18+$E$18),$D$18/$E$18,0) | M30: =IF(AND(10>$C$18,10<=$C$18+$E$18),$D$18/$E$18,0)
A31: DEPRECIAÇÃO CORRIGIDA | B31: R$/ano | C31: =SUM(C24:C30) | D31: =SUM(D24:D30) | E31: =SUM(E24:E30) | F31: =SUM(F24:F30) | G31: =SUM(G24:G30) | H31: =SUM(H24:H30) | I31: =SUM(I24:I30) | J31: =SUM(J24:J30) | ... M31: =SUM(M24:M30)
A32: Depreciação acumulada | B32: R$ | C32: =C31 | D32: =C32+D31 | E32: =D32+E31 | F32: =E32+F31 | G32: =F32+G31 | H32: =G32+H31 | I32: =H32+I31 | J32: =I32+J31 | K32: =J32+K31 | ... M32: =L32+M31
A33: Valor contábil líquido do imobilizado | B33: R$ | C33: =$D$21-C32 | D33: =$D$21-D32 | E33: =$D$21-E32 | F33: =$D$21-F32 | G33: =$D$21-G32 | H33: =$D$21-H32 | I33: =$D$21-I32 | J33: =$D$21-J32 | ... M33: =$D$21-M32 | O33: Cálculo: ativo total − depreciação acumulada. Usado no valor residual do fluxo de caixa.
A35: C. ANTES E DEPOIS — o que o erro custava
A36: Depreciação da origem | B36: R$/ano | C36: 0 | D36: 885858.58 | E36: 885858.58 | F36: 885858.58 | G36: 885858.58 | H36: 885858.58 | I36: 885858.58 | J36: 885858.58 | K36: 885858.58 | L36: 885858.58 | M36: 885858.58 | O36: Origem: 20. Custos Unitários!D136, constante nos 10 anos. Zero no ano 0.
A37: Depreciação corrigida | B37: R$/ano | C37: =C31 | D37: =D31 | E37: =E31 | F37: =F31 | G37: =G31 | H37: =H31 | I37: =I31 | J37: =J31 | ... M37: =M31
A38: Diferença (corrigida − origem) | B38: R$/ano | C38: =C37-C36 | D38: =D37-D36 | E38: =E37-E36 | F38: =F37-F36 | G38: =G37-G36 | H38: =H37-H36 | I38: =I37-I36 | J38: =J37-J36 | ... M38: =M37-M36
A39: Efeito no imposto | B39: R$/ano | C39: =-C38*'2. Inputs'!$C$76 | D39: =-D38*'2. Inputs'!$C$76 | E39: =-E38*'2. Inputs'!$C$76 | F39: =-F38*'2. Inputs'!$C$76 | G39: =-G38*'2. Inputs'!$C$76 | H39: =-H38*'2. Inputs'!$C$76 | I39: =-I38*'2. Inputs'!$C$76 | J39: =-J38*'2. Inputs'!$C$76 | ... M39: =-M38*'2. Inputs'!$C$76 | O39: Mais depreciação = menos lucro tributável = menos imposto. Alíquota em 2. Inputs!C76. Sinal negativo = imposto a menos.
A40: Efeito líquido no caixa | B40: R$/ano | C40: =C38*'2. Inputs'!$C$76 | D40: =D38*'2. Inputs'!$C$76 | E40: =E38*'2. Inputs'!$C$76 | F40: =F38*'2. Inputs'!$C$76 | G40: =G38*'2. Inputs'!$C$76 | H40: =H38*'2. Inputs'!$C$76 | I40: =I38*'2. Inputs'!$C$76 | J40: =J38*'2. Inputs'!$C$76 | ... M40: =M38*'2. Inputs'!$C$76 | O40: A depreciação sai do lucro e volta no fluxo: o efeito de caixa é só o escudo fiscal. Sinal positivo = caixa a mais.
A42: D. OS QUATRO DEFEITOS DA ORIGEM
A43: D1 — Base incompleta | C43: A origem depreciava R$ 16.185.053. A base correta do ano 0 é R$ 16.201.826. Faltavam R$ 16.773: itens de laboratório pegos antes do acréscimo de 15%, e bancada (R$ 3.800) e armário de laboratório (R$ 4.048) não classificados em ativo nenhum. | O43: subdepreciava
A44: D2 — Vida útil ignorada | C44: "Material de informática e móveis" tem vida de 5 anos na própria tabela da origem (20. Custos Unitários!B130) e era depreciado nos 10 anos do horizonte: R$ 313.844 sobre uma base de R$ 156.922. 200% do custo. | O44: superdepreciava R$ 156.922
A45: D3 — Reinvestimento sem depreciação | C45: R$ 594 mil de CAPEX corrigido entra no fluxo nos anos 4, 5 e 7 e nunca aparecia na base. A tabela D133:D135 só olhava o ano 0. | O45: subdepreciava
A46: D4 — Base de volume inconsistente | C46: A depreciação virava custo fixo unitário dividida por unidades PRODUZIDAS e voltava ao resultado multiplicada por unidades VENDIDAS. No ano 1 deduzia R$ 974.270 e somava de volta R$ 885.859: R$ 88.412 de caixa fantasma, todo ano. | O46: inflava o fluxo de caixa
A47: Não era erro | C47: O terreno (R$ 908.612) está fora da base — correto, terreno não deprecia. E a depreciação era deduzida antes do imposto e somada de volta no fluxo: o mecanismo do escudo fiscal estava certo. O problema era o valor, não o lugar. | O47: —

Sheet 4. DRE
A1: DRE — FORMATO FP&A
A2: Margem em cada linha. Na origem o resultado estava espalhado entre 20. Custos Unitários, 21. PVU e 22.2 Fluxo de Caixa, e não havia EBITDA em lugar nenhum.
A7: Ano | C7: 0 | D7: 1 | E7: 2 | F7: 3 | G7: 4 | H7: 5 | I7: 6 | J7: 7 | K7: 8 | L7: 9 | M7: 10 | O7: Observação
A8: Exercício | C8: 2023 | D8: 2024 | E8: 2025 | F8: 2026 | G8: 2027 | H8: 2028 | I8: 2029 | J8: 2030 | K8: 2031 | L8: 2032 | M8: 2033
A10: A. APURAÇÃO DO PREÇO (custo total + markup — a lógica da origem, com cada parcela visível)
A11: Volume | B11: un/ano | C11: — | D11: ='2. Inputs'!D14 | E11: ='2. Inputs'!E14 | F11: ='2. Inputs'!F14 | G11: ='2. Inputs'!G14 | H11: ='2. Inputs'!H14 | I11: ='2. Inputs'!I14 | J11: ='2. Inputs'!J14 | K11: ='2. Inputs'!K14 | ... M11: ='2. Inputs'!M14
A12: Custo variável | B12: R$ | C12: — | D12: =D11*'2. Inputs'!D45 | E12: =E11*'2. Inputs'!E45 | F12: =F11*'2. Inputs'!F45 | G12: =G11*'2. Inputs'!G45 | H12: =H11*'2. Inputs'!H45 | I12: =I11*'2. Inputs'!I45 | J12: =J11*'2. Inputs'!J45 | K12: =K11*'2. Inputs'!K45 | ... M12: =M11*'2. Inputs'!M45
A13: Frete sobre vendas | B13: R$ | C13: — | D13: =D11*'2. Inputs'!D29 | E13: =E11*'2. Inputs'!E29 | F13: =F11*'2. Inputs'!F29 | G13: =G11*'2. Inputs'!G29 | H13: =H11*'2. Inputs'!H29 | I13: =I11*'2. Inputs'!I29 | J13: =J11*'2. Inputs'!J29 | K13: =K11*'2. Inputs'!K29 | ... M13: =M11*'2. Inputs'!M29 | O13: Volume x frete unitário ponderado pelo mix regional.
A14: Custo fixo de estrutura | B14: R$ | C14: — | D14: ='2. Inputs'!D46 | E14: ='2. Inputs'!E46 | F14: ='2. Inputs'!F46 | G14: ='2. Inputs'!G46 | H14: ='2. Inputs'!H46 | I14: ='2. Inputs'!I46 | J14: ='2. Inputs'!J46 | K14: ='2. Inputs'!K46 | ... M14: ='2. Inputs'!M46
A15: Manutenção e seguro | B15: R$ | C15: — | D15: =('2. Inputs'!D47+'2. Inputs'!D48)*'2. Inputs'!D54 | E15: =('2. Inputs'!E47+'2. Inputs'!E48)*'2. Inputs'!E54 | F15: =('2. Inputs'!F47+'2. Inputs'!F48)*'2. Inputs'!F54 | G15: =('2. Inputs'!G47+'2. Inputs'!G48)*'2. Inputs'!G54 | H15: =('2. Inputs'!H47+'2. Inputs'!H48)*'2. Inputs'!H54 | I15: =('2. Inputs'!I47+'2. Inputs'!I48)*'2. Inputs'!I54 | J15: =('2. Inputs'!J47+'2. Inputs'!J48)*'2. Inputs'!J54 | K15: =('2. Inputs'!K47+'2. Inputs'!K48)*'2. Inputs'!K54 | ... M15: =('2. Inputs'!M47+'2. Inputs'!M48)*'2. Inputs'!M54 | O15: (3,0% + 1,5%) x CAPEX acumulado.
A16: Contingência | B16: R$ | C16: — | D16: ='2. Inputs'!D49*'2. Inputs'!D54 | E16: ='2. Inputs'!E49*'2. Inputs'!E54 | F16: ='2. Inputs'!F49*'2. Inputs'!F54 | G16: ='2. Inputs'!G49*'2. Inputs'!G54 | H16: ='2. Inputs'!H49*'2. Inputs'!H54 | I16: ='2. Inputs'!I49*'2. Inputs'!I54 | J16: ='2. Inputs'!J49*'2. Inputs'!J54 | K16: ='2. Inputs'!K49*'2. Inputs'!K54 | ... M16: ='2. Inputs'!M49*'2. Inputs'!M54 | O16: % x CAPEX acumulado — alavanca de cenário.
A17: Depreciação | B17: R$ | C17: — | D17: ='3. Depreciacao'!D31 | E17: ='3. Depreciacao'!E31 | F17: ='3. Depreciacao'!F31 | G17: ='3. Depreciacao'!G31 | H17: ='3. Depreciacao'!H31 | I17: ='3. Depreciacao'!I31 | J17: ='3. Depreciacao'!J31 | K17: ='3. Depreciacao'!K31 | ... M17: ='3. Depreciacao'!M31
A18: CUSTO TOTAL | B18: R$ | D18: =SUM(D12:D17) | E18: =SUM(E12:E17) | F18: =SUM(F12:F17) | G18: =SUM(G12:G17) | H18: =SUM(H12:H17) | I18: =SUM(I12:I17) | J18: =SUM(J12:J17) | K18: =SUM(K12:K17) | ... M18: =SUM(M12:M17)
A19: Custo total unitário (CTU) | B19: R$/un | D19: =D18/D11 | E19: =E18/E11 | F19: =F18/F11 | G19: =G18/G11 | H19: =H18/H11 | I19: =I18/I11 | J19: =J18/J11 | K19: =K18/K11 | ... M19: =M18/M11 | O19: Na origem o CTU estava DIGITADO em 21. PVU!C3:C12 e já não batia com o custo calculado.
A20: Markup total | B20: % | D20: ='2. Inputs'!D40 | E20: ='2. Inputs'!E40 | F20: ='2. Inputs'!F40 | G20: ='2. Inputs'!G40 | H20: ='2. Inputs'!H40 | I20: ='2. Inputs'!I40 | J20: ='2. Inputs'!J40 | K20: ='2. Inputs'!K40 | ... M20: ='2. Inputs'!M40
A21: PREÇO BRUTO UNITÁRIO | B21: R$/un | D21: =IF('2. Inputs'!$C$38=1,D19/(1-D20),'2. Inputs'!D39) | E21: =IF('2. Inputs'!$C$38=1,E19/(1-E20),'2. Inputs'!E39) | F21: =IF('2. Inputs'!$C$38=1,F19/(1-F20),'2. Inputs'!F39) | G21: =IF('2. Inputs'!$C$38=1,G19/(1-G20),'2. Inputs'!G39) | H21: =IF('2. Inputs'!$C$38=1,H19/(1-H20),'2. Inputs'!H39) | I21: =IF('2. Inputs'!$C$38=1,I19/(1-I20),'2. Inputs'!I39) | J21: =IF('2. Inputs'!$C$38=1,J19/(1-J20),'2. Inputs'!J39) | K21: =IF('2. Inputs'!$C$38=1,K19/(1-K20),'2. Inputs'!K39) | ... M21: =IF('2. Inputs'!$C$38=1,M19/(1-M20),'2. Inputs'!M39) | O21: Modo 1: CTU / (1 − markup). Modo 2: preço de mercado da aba 2. Inputs.
A23: B. DEMONSTRAÇÃO DE RESULTADO
A24: Volume | B24: un/ano | C24: — | D24: =D11 | E24: =E11 | F24: =F11 | G24: =G11 | H24: =H11 | I24: =I11 | J24: =J11 | K24: =K11 | ... M24: =M11
A25: Preço bruto unitário | B25: R$/un | D25: =D21 | E25: =E21 | F25: =F21 | G25: =G21 | H25: =H21 | I25: =I21 | J25: =J21 | K25: =K21 | ... M25: =M21
A26: RECEITA BRUTA | B26: R$ | D26: =D24*D25 | E26: =E24*E25 | F26: =F24*F25 | G26: =G24*G25 | H26: =H24*H25 | I26: =I24*I25 | J26: =J24*J25 | K26: =K24*K25 | ... M26: =M24*M25
A27: (−) ICMS | B27: R$ | D27: =-'2. Inputs'!D32*D26 | E27: =-'2. Inputs'!E32*E26 | F27: =-'2. Inputs'!F32*F26 | G27: =-'2. Inputs'!G32*G26 | H27: =-'2. Inputs'!H32*H26 | I27: =-'2. Inputs'!I32*I26 | J27: =-'2. Inputs'!J32*J26 | K27: =-'2. Inputs'!K32*K26 | ... M27: =-'2. Inputs'!M32*M26
A28: (−) PIS e COFINS | B28: R$ | D28: =-('2. Inputs'!D33+'2. Inputs'!D34)*D26 | E28: =-('2. Inputs'!E33+'2. Inputs'!E34)*E26 | F28: =-('2. Inputs'!F33+'2. Inputs'!F34)*F26 | G28: =-('2. Inputs'!G33+'2. Inputs'!G34)*G26 | H28: =-('2. Inputs'!H33+'2. Inputs'!H34)*H26 | I28: =-('2. Inputs'!I33+'2. Inputs'!I34)*I26 | J28: =-('2. Inputs'!J33+'2. Inputs'!J34)*J26 | K28: =-('2. Inputs'!K33+'2. Inputs'!K34)*K26 | ... M28: =-('2. Inputs'!M33+'2. Inputs'!M34)*M26
A29: RECEITA LÍQUIDA | B29: R$ | D29: =SUM(D26:D28) | E29: =SUM(E26:E28) | F29: =SUM(F26:F28) | G29: =SUM(G26:G28) | H29: =SUM(H26:H28) | I29: =SUM(I26:I28) | J29: =SUM(J26:J28) | K29: =SUM(K26:K28) | ... M29: =SUM(M26:M28)
A30: Deduções sobre receita bruta | B30: % RB | D30: =-(D27+D28)/D26 | E30: =-(E27+E28)/E26 | F30: =-(F27+F28)/F26 | G30: =-(G27+G28)/G26 | H30: =-(H27+H28)/H26 | I30: =-(I27+I28)/I26 | J30: =-(J27+J28)/J26 | K30: =-(K27+K28)/K26 | ... M30: =-(M27+M28)/M26
A31: (−) Custo variável | B31: R$ | D31: =-D12 | E31: =-E12 | F31: =-F12 | G31: =-G12 | H31: =-H12 | I31: =-I12 | J31: =-J12 | K31: =-K12 | ... M31: =-M12
A32: (−) Frete sobre vendas | B32: R$ | D32: =-D13 | E32: =-E13 | F32: =-F13 | G32: =-G13 | H32: =-H13 | I32: =-I13 | J32: =-J13 | K32: =-K13 | ... M32: =-M13
A33: (−) Comissão sobre vendas | B33: R$ | D33: =-'2. Inputs'!D35*D26 | E33: =-'2. Inputs'!E35*E26 | F33: =-'2. Inputs'!F35*F26 | G33: =-'2. Inputs'!G35*G26 | H33: =-'2. Inputs'!H35*H26 | I33: =-'2. Inputs'!I35*I26 | J33: =-'2. Inputs'!J35*J26 | K33: =-'2. Inputs'!K35*K26 | ... M33: =-'2. Inputs'!M35*M26 | O33: (confirmar) — na origem esta parcela de 3% estava DENTRO do markup e nunca virou despesa: virava margem escondida.
A34: MARGEM DE CONTRIBUIÇÃO | B34: R$ | D34: =SUM(D31:D33)+D29 | E34: =SUM(E31:E33)+E29 | F34: =SUM(F31:F33)+F29 | G34: =SUM(G31:G33)+G29 | H34: =SUM(H31:H33)+H29 | I34: =SUM(I31:I33)+I29 | J34: =SUM(J31:J33)+J29 | K34: =SUM(K31:K33)+K29 | ... M34: =SUM(M31:M33)+M29
A35: Margem de contribuição | B35: % RL | D35: =D34/D29 | E35: =E34/E29 | F35: =F34/F29 | G35: =G34/G29 | H35: =H34/H29 | I35: =I34/I29 | J35: =J34/J29 | K35: =K34/K29 | ... M35: =M34/M29
A36: (−) Custo fixo de estrutura | B36: R$ | D36: =-D14 | E36: =-E14 | F36: =-F14 | G36: =-G14 | H36: =-H14 | I36: =-I14 | J36: =-J14 | K36: =-K14 | ... M36: =-M14
A37: (−) Manutenção e seguro | B37: R$ | D37: =-D15 | E37: =-E15 | F37: =-F15 | G37: =-G15 | H37: =-H15 | I37: =-I15 | J37: =-J15 | K37: =-K15 | ... M37: =-M15
A38: (−) Contingência | B38: R$ | D38: =-D16 | E38: =-E16 | F38: =-F16 | G38: =-G16 | H38: =-H16 | I38: =-I16 | J38: =-J16 | K38: =-K16 | ... M38: =-M16
A39: EBITDA | B39: R$ | D39: =D34+SUM(D36:D38) | E39: =E34+SUM(E36:E38) | F39: =F34+SUM(F36:F38) | G39: =G34+SUM(G36:G38) | H39: =H34+SUM(H36:H38) | I39: =I34+SUM(I36:I38) | J39: =J34+SUM(J36:J38) | K39: =K34+SUM(K36:K38) | ... M39: =M34+SUM(M36:M38)
A40: Margem EBITDA | B40: % RL | D40: =D39/D29 | E40: =E39/E29 | F40: =F39/F29 | G40: =G39/G29 | H40: =H39/H29 | I40: =I39/I29 | J40: =J39/J29 | K40: =K39/K29 | ... M40: =M39/M29
A41: (−) Depreciação | B41: R$ | D41: =-D17 | E41: =-E17 | F41: =-F17 | G41: =-G17 | H41: =-H17 | I41: =-I17 | J41: =-J17 | K41: =-K17 | ... M41: =-M17
A42: EBIT | B42: R$ | D42: =D39+D41 | E42: =E39+E41 | F42: =F39+F41 | G42: =G39+G41 | H42: =H39+H41 | I42: =I39+I41 | J42: =J39+J41 | K42: =K39+K41 | ... M42: =M39+M41
A43: Margem EBIT | B43: % RL | D43: =D42/D29 | E43: =E42/E29 | F43: =F42/F29 | G43: =G42/G29 | H43: =H42/H29 | I43: =I42/I29 | J43: =J42/J29 | K43: =K42/K29 | ... M43: =M42/M29
A44: (−) IRPJ + adicional | B44: R$ | D44: =-IF(D42>0,'2. Inputs'!D58*D42+'2. Inputs'!D59*MAX(0,D42-'2. Inputs'!D60),0) | E44: =-IF(E42>0,'2. Inputs'!E58*E42+'2. Inputs'!E59*MAX(0,E42-'2. Inputs'!E60),0) | F44: =-IF(F42>0,'2. Inputs'!F58*F42+'2. Inputs'!F59*MAX(0,F42-'2. Inputs'!F60),0) | G44: =-IF(G42>0,'2. Inputs'!G58*G42+'2. Inputs'!G59*MAX(0,G42-'2. Inputs'!G60),0) | H44: =-IF(H42>0,'2. Inputs'!H58*H42+'2. Inputs'!H59*MAX(0,H42-'2. Inputs'!H60),0) | I44: =-IF(I42>0,'2. Inputs'!I58*I42+'2. Inputs'!I59*MAX(0,I42-'2. Inputs'!I60),0) | J44: =-IF(J42>0,'2. Inputs'!J58*J42+'2. Inputs'!J59*MAX(0,J42-'2. Inputs'!J60),0) | K44: =-IF(K42>0,'2. Inputs'!K58*K42+'2. Inputs'!K59*MAX(0,K42-'2. Inputs'!K60),0) | ... M44: =-IF(M42>0,'2. Inputs'!M58*M42+'2. Inputs'!M59*MAX(0,M42-'2. Inputs'!M60),0) | O44: A origem não protegia lucro abaixo do limite do adicional nem prejuízo.
A45: (−) CSLL | B45: R$ | D45: =-IF(D42>0,'2. Inputs'!D61*D42,0) | E45: =-IF(E42>0,'2. Inputs'!E61*E42,0) | F45: =-IF(F42>0,'2. Inputs'!F61*F42,0) | G45: =-IF(G42>0,'2. Inputs'!G61*G42,0) | H45: =-IF(H42>0,'2. Inputs'!H61*H42,0) | I45: =-IF(I42>0,'2. Inputs'!I61*I42,0) | J45: =-IF(J42>0,'2. Inputs'!J61*J42,0) | K45: =-IF(K42>0,'2. Inputs'!K61*K42,0) | ... M45: =-IF(M42>0,'2. Inputs'!M61*M42,0)
A46: LUCRO LÍQUIDO | B46: R$ | D46: =D42+D44+D45 | E46: =E42+E44+E45 | F46: =F42+F44+F45 | G46: =G42+G44+G45 | H46: =H42+H44+H45 | I46: =I42+I44+I45 | J46: =J42+J44+J45 | K46: =K42+K44+K45 | ... M46: =M42+M44+M45
...

Sheet 5. Fluxo de Caixa
A1: FLUXO DE CAIXA LIVRE
A2: Capital de giro reconstruído sobre prazos declarados; CAPEX corrigido; depreciação da aba 3. Não há dívida, logo o FCL é também o fluxo do acionista.
A7: Ano | C7: 0 | D7: 1 | E7: 2 | F7: 3 | G7: 4 | H7: 5 | I7: 6 | J7: 7 | K7: 8 | L7: 9 | M7: 10 | O7: Observação
A8: Exercício | C8: 2023 | D8: 2024 | E8: 2025 | F8: 2026 | G8: 2027 | H8: 2028 | I8: 2029 | J8: 2030 | K8: 2031 | L8: 2032 | M8: 2033
A10: A. CAPITAL DE GIRO
A11: Contas a receber | B11: R$ | D11: ='2. Inputs'!D64/'2. Inputs'!D68*'4. DRE'!D26 | E11: ='2. Inputs'!E64/'2. Inputs'!E68*'4. DRE'!E26 | F11: ='2. Inputs'!F64/'2. Inputs'!F68*'4. DRE'!F26 | G11: ='2. Inputs'!G64/'2. Inputs'!G68*'4. DRE'!G26 | H11: ='2. Inputs'!H64/'2. Inputs'!H68*'4. DRE'!H26 | I11: ='2. Inputs'!I64/'2. Inputs'!I68*'4. DRE'!I26 | J11: ='2. Inputs'!J64/'2. Inputs'!J68*'4. DRE'!J26 | K11: ='2. Inputs'!K64/'2. Inputs'!K68*'4. DRE'!K26 | ... M11: ='2. Inputs'!M64/'2. Inputs'!M68*'4. DRE'!M26 | O11: PMR x receita bruta / 360.
A12: Estoques | B12: R$ | D12: ='2. Inputs'!D65/'2. Inputs'!D68*(-'4. DRE'!D31-'4. DRE'!D32) | E12: ='2. Inputs'!E65/'2. Inputs'!E68*(-'4. DRE'!E31-'4. DRE'!E32) | F12: ='2. Inputs'!F65/'2. Inputs'!F68*(-'4. DRE'!F31-'4. DRE'!F32) | G12: ='2. Inputs'!G65/'2. Inputs'!G68*(-'4. DRE'!G31-'4. DRE'!G32) | H12: ='2. Inputs'!H65/'2. Inputs'!H68*(-'4. DRE'!H31-'4. DRE'!H32) | I12: ='2. Inputs'!I65/'2. Inputs'!I68*(-'4. DRE'!I31-'4. DRE'!I32) | J12: ='2. Inputs'!J65/'2. Inputs'!J68*(-'4. DRE'!J31-'4. DRE'!J32) | K12: ='2. Inputs'!K65/'2. Inputs'!K68*(-'4. DRE'!K31-'4. DRE'!K32) | ... M12: ='2. Inputs'!M65/'2. Inputs'!M68*(-'4. DRE'!M31-'4. DRE'!M32) | O12: Giro de estoque x (custo variável + frete) / 360.
A13: Caixa mínimo | B13: R$ | D13: ='2. Inputs'!D67/'2. Inputs'!D68*(-'4. DRE'!D31-'4. DRE'!D32-'4. DRE'!D33-'4. DRE'!D36-'4. DRE'!D37-'4. DRE'!D38) | E13: ='2. Inputs'!E67/'2. Inputs'!E68*(-'4. DRE'!E31-'4. DRE'!E32-'4. DRE'!E33-'4. DRE'!E36-'4. DRE'!E37-'4. DRE'!E38) | F13: ='2. Inputs'!F67/'2. Inputs'!F68*(-'4. DRE'!F31-'4. DRE'!F32-'4. DRE'!F33-'4. DRE'!F36-'4. DRE'!F37-'4. DRE'!F38) | G13: ='2. Inputs'!G67/'2. Inputs'!G68*(-'4. DRE'!G31-'4. DRE'!G32-'4. DRE'!G33-'4. DRE'!G36-'4. DRE'!G37-'4. DRE'!G38) | H13: ='2. Inputs'!H67/'2. Inputs'!H68*(-'4. DRE'!H31-'4. DRE'!H32-'4. DRE'!H33-'4. DRE'!H36-'4. DRE'!H37-'4. DRE'!H38) | I13: ='2. Inputs'!I67/'2. Inputs'!I68*(-'4. DRE'!I31-'4. DRE'!I32-'4. DRE'!I33-'4. DRE'!I36-'4. DRE'!I37-'4. DRE'!I38) | J13: ='2. Inputs'!J67/'2. Inputs'!J68*(-'4. DRE'!J31-'4. DRE'!J32-'4. DRE'!J33-'4. DRE'!J36-'4. DRE'!J37-'4. DRE'!J38) | K13: ='2. Inputs'!K67/'2. Inputs'!K68*(-'4. DRE'!K31-'4. DRE'!K32-'4. DRE'!K33-'4. DRE'!K36-'4. DRE'!K37-'4. DRE'!K38) | ... M13: ='2. Inputs'!M67/'2. Inputs'!M68*(-'4. DRE'!M31-'4. DRE'!M32-'4. DRE'!M33-'4. DRE'!M36-'4. DRE'!M37-'4. DRE'!M38) | O13: Dias x custo CAIXA total / 360. A origem usava o custo total, com depreciação dentro — depreciação não exige caixa.
A14: (−) Fornecedores | B14: R$ | D14: =-'2. Inputs'!D66/'2. Inputs'!D68*(-'4. DRE'!D31-'4. DRE'!D32) | E14: =-'2. Inputs'!E66/'2. Inputs'!E68*(-'4. DRE'!E31-'4. DRE'!E32) | F14: =-'2. Inputs'!F66/'2. Inputs'!F68*(-'4. DRE'!F31-'4. DRE'!F32) | G14: =-'2. Inputs'!G66/'2. Inputs'!G68*(-'4. DRE'!G31-'4. DRE'!G32) | H14: =-'2. Inputs'!H66/'2. Inputs'!H68*(-'4. DRE'!H31-'4. DRE'!H32) | I14: =-'2. Inputs'!I66/'2. Inputs'!I68*(-'4. DRE'!I31-'4. DRE'!I32) | J14: =-'2. Inputs'!J66/'2. Inputs'!J68*(-'4. DRE'!J31-'4. DRE'!J32) | K14: =-'2. Inputs'!K66/'2. Inputs'!K68*(-'4. DRE'!K31-'4. DRE'!K32) | ... M14: =-'2. Inputs'!M66/'2. Inputs'!M68*(-'4. DRE'!M31-'4. DRE'!M32) | O14: PMP x (custo variável + frete) / 360. Na origem a rotação do leite no ano 2 estava 260 em vez de 12 (A-03).
A15: NECESSIDADE DE CAPITAL DE GIRO | B15: R$ | C15: =D15 | D15: =SUM(D11:D14) | E15: =SUM(E11:E14) | F15: =SUM(F11:F14) | G15: =SUM(G11:G14) | H15: =SUM(H11:H14) | I15: =SUM(I11:I14) | J15: =SUM(J11:J14) | K15: =SUM(K11:K14) | ... M15: =SUM(M11:M14) | O15: Ano 0 = necessidade do ano 1: o giro é financiado antes de operar.
A16: Δ capital de giro | B16: R$ | C16: =C15 | D16: =D15-C15 | E16: =E15-D15 | F16: =F15-E15 | G16: =G15-F15 | H16: =H15-G15 | I16: =I15-H15 | J16: =J15-I15 | K16: =K15-J15 | ... M16: =M15-L15
A17: Capital de giro sobre receita bruta | B17: % RB | D17: =IFERROR(D15/'4. DRE'!D26,"") | E17: =IFERROR(E15/'4. DRE'!E26,"") | F17: =IFERROR(F15/'4. DRE'!F26,"") | G17: =IFERROR(G15/'4. DRE'!G26,"") | H17: =IFERROR(H15/'4. DRE'!H26,"") | I17: =IFERROR(I15/'4. DRE'!I26,"") | J17: =IFERROR(J15/'4. DRE'!J26,"") | K17: =IFERROR(K15/'4. DRE'!K26,"") | ... M17: =IFERROR(M15/'4. DRE'!M26,"")
A19: B. FLUXO DE CAIXA LIVRE
A20: EBIT | B20: R$ | D20: ='4. DRE'!D42 | E20: ='4. DRE'!E42 | F20: ='4. DRE'!F42 | G20: ='4. DRE'!G42 | H20: ='4. DRE'!H42 | I20: ='4. DRE'!I42 | J20: ='4. DRE'!J42 | K20: ='4. DRE'!K42 | ... M20: ='4. DRE'!M42
A21: (−) IRPJ + adicional | B21: R$ | D21: ='4. DRE'!D44 | E21: ='4. DRE'!E44 | F21: ='4. DRE'!F44 | G21: ='4. DRE'!G44 | H21: ='4. DRE'!H44 | I21: ='4. DRE'!I44 | J21: ='4. DRE'!J44 | K21: ='4. DRE'!K44 | ... M21: ='4. DRE'!M44
A22: (−) CSLL | B22: R$ | D22: ='4. DRE'!D45 | E22: ='4. DRE'!E45 | F22: ='4. DRE'!F45 | G22: ='4. DRE'!G45 | H22: ='4. DRE'!H45 | I22: ='4. DRE'!I45 | J22: ='4. DRE'!J45 | K22: ='4. DRE'!K45 | ... M22: ='4. DRE'!M45
A23: NOPAT | B23: R$ | D23: =SUM(D20:D22) | E23: =SUM(E20:E22) | F23: =SUM(F20:F22) | G23: =SUM(G20:G22) | H23: =SUM(H20:H22) | I23: =SUM(I20:I22) | J23: =SUM(J20:J22) | K23: =SUM(K20:K22) | ... M23: =SUM(M20:M22) | O23: Lucro operacional após imposto. Sem dívida, NOPAT = lucro líquido.
A24: (+) Depreciação | B24: R$ | D24: ='3. Depreciacao'!D31 | E24: ='3. Depreciacao'!E31 | F24: ='3. Depreciacao'!F31 | G24: ='3. Depreciacao'!G31 | H24: ='3. Depreciacao'!H31 | I24: ='3. Depreciacao'!I31 | J24: ='3. Depreciacao'!J31 | K24: ='3. Depreciacao'!K31 | ... M24: ='3. Depreciacao'!M31 | O24: Despesa sem caixa: sai do lucro e volta aqui.
A25: (−) Δ capital de giro | B25: R$ | C25: =-C16 | D25: =-D16 | E25: =-E16 | F25: =-F16 | G25: =-G16 | H25: =-H16 | I25: =-I16 | J25: =-J16 | ... M25: =-M16
A26: (−) CAPEX | B26: R$ | C26: =-'2. Inputs'!C53 | D26: =-'2. Inputs'!D53 | E26: =-'2. Inputs'!E53 | F26: =-'2. Inputs'!F53 | G26: =-'2. Inputs'!G53 | H26: =-'2. Inputs'!H53 | I26: =-'2. Inputs'!I53 | J26: =-'2. Inputs'!J53 | ... M26: =-'2. Inputs'!M53
A27: (+) Recuperação do capital de giro | B27: R$ | C27: =IF(C$7=10,C15,0) | D27: =IF(D$7=10,D15,0) | E27: =IF(E$7=10,E15,0) | F27: =IF(F$7=10,F15,0) | G27: =IF(G$7=10,G15,0) | H27: =IF(H$7=10,H15,0) | I27: =IF(I$7=10,I15,0) | J27: =IF(J$7=10,J15,0) | ... M27: =IF(M$7=10,M15,0) | O27: Liberação integral no fim do horizonte. Na origem isso acontecia por acidente: a célula do ano 10 estava vazia.
A28: FLUXO DE CAIXA LIVRE | B28: R$ | C28: =C23+SUM(C24:C27) | D28: =D23+SUM(D24:D27) | E28: =E23+SUM(E24:E27) | F28: =F23+SUM(F24:F27) | G28: =G23+SUM(G24:G27) | H28: =H23+SUM(H24:H27) | I28: =I23+SUM(I24:I27) | J28: =J23+SUM(J24:J27) | ... M28: =M23+SUM(M24:M27)
A29: FCL acumulado | B29: R$ | C29: =C28 | D29: =C29+D28 | E29: =D29+E28 | F29: =E29+F28 | G29: =F29+G28 | H29: =G29+H28 | I29: =H29+I28 | J29: =I29+J28 | K29: =J29+K28 | ... M29: =L29+M28
A31: C. COMPARAÇÃO COM O FLUXO DA ORIGEM
A32: FCL da origem | B32: R$ | C32: -21598508 | D32: 7986626.2 | E32: 9362640.7 | F32: 10207909 | G32: 6380315.9 | H32: 14515259 | I32: 16744066 | J32: 20668974 | K32: 24904740 | L32: 29857465 | M32: 51228664 | O32: Origem: 22.2 Fluxo de Caixa!G10:G20.
A33: FCL do modelo | B33: R$ | C33: =C28 | D33: =D28 | E33: =E28 | F33: =F28 | G33: =G28 | H33: =H28 | I33: =I28 | J33: =J28 | ... M33: =M28
A34: Diferença | B34: R$ | C34: =C28-C32 | D34: =D28-D32 | E34: =E28-E32 | F34: =F28-F32 | G34: =G28-G32 | H34: =H28-H32 | I34: =I28-I32 | J34: =J28-J32 | ... M34: =M28-M32 | O34: Volume = produzido (não vendido), comissão de 3% virou despesa, CAPEX de 2028 corrigido, capital de giro reconstruído.

Sheet 6. Valuation
A1: VALUATION — WACC NO LUGAR DA SELIC
A2: A origem descontava a 12,25%, "a Selic vigente em outubro de 2020", sem prêmio de risco nenhum. Aqui a taxa é construída e o impacto no VPL fica explícito.
A7: Ano | C7: 0 | D7: 1 | E7: 2 | F7: 3 | G7: 4 | H7: 5 | I7: 6 | J7: 7 | K7: 8 | L7: 9 | M7: 10 | O7: Observação
A8: Exercício | C8: 2023 | D8: 2024 | E8: 2025 | F8: 2026 | G8: 2027 | H8: 2028 | I8: 2029 | J8: 2030 | K8: 2031 | L8: 2032 | M8: 2033
A10: A. FLUXO DESCONTADO
A11: Fluxo de caixa livre | B11: R$ | C11: ='5. Fluxo de Caixa'!C28 | D11: ='5. Fluxo de Caixa'!D28 | E11: ='5. Fluxo de Caixa'!E28 | F11: ='5. Fluxo de Caixa'!F28 | G11: ='5. Fluxo de Caixa'!G28 | H11: ='5. Fluxo de Caixa'!H28 | I11: ='5. Fluxo de Caixa'!I28 | J11: ='5. Fluxo de Caixa'!J28 | ... M11: ='5. Fluxo de Caixa'!M28
A12: Fator de desconto @ WACC | B12: x | C12: =1/(1+'2. Inputs'!$C$81)^C$7 | D12: =1/(1+'2. Inputs'!$C$81)^D$7 | E12: =1/(1+'2. Inputs'!$C$81)^E$7 | F12: =1/(1+'2. Inputs'!$C$81)^F$7 | G12: =1/(1+'2. Inputs'!$C$81)^G$7 | H12: =1/(1+'2. Inputs'!$C$81)^H$7 | I12: =1/(1+'2. Inputs'!$C$81)^I$7 | J12: =1/(1+'2. Inputs'!$C$81)^J$7 | ... M12: =1/(1+'2. Inputs'!$C$81)^M$7 | O12: Cálculo: 1/(1+WACC)^ano.
A13: FCL descontado @ WACC | B13: R$ | C13: =C11*C12 | D13: =D11*D12 | E13: =E11*E12 | F13: =F11*F12 | G13: =G11*G12 | H13: =H11*H12 | I13: =I11*I12 | J13: =J11*J12 | ... M13: =M11*M12
A14: FCL descontado acumulado | B14: R$ | C14: =C13 | D14: =C14+D13 | E14: =D14+E13 | F14: =E14+F13 | G14: =F14+G13 | H14: =G14+H13 | I14: =H14+I13 | J14: =I14+J13 | K14: =J14+K13 | ... M14: =L14+M13
A15: FCL descontado @ Selic 12,25% (critério da origem) | B15: R$ | C15: =C11/(1+'2. Inputs'!$C$82)^C$7 | D15: =D11/(1+'2. Inputs'!$C$82)^D$7 | E15: =E11/(1+'2. Inputs'!$C$82)^E$7 | F15: =F11/(1+'2. Inputs'!$C$82)^F$7 | G15: =G11/(1+'2. Inputs'!$C$82)^G$7 | H15: =H11/(1+'2. Inputs'!$C$82)^H$7 | I15: =I11/(1+'2. Inputs'!$C$82)^I$7 | J15: =J11/(1+'2. Inputs'!$C$82)^J$7 | ... M15: =M11/(1+'2. Inputs'!$C$82)^M$7
A17: B. INDICADORES
A18: VPL @ WACC | C18: =SUM(C13:M13) | O18: Sem valor terminal — comparável ao critério da origem.
A19: VPL @ Selic 12,25% | C19: =SUM(C15:M15) | O19: Mesmo fluxo, taxa da origem.
A20: Diferença — o preço de usar a Selic como taxa de desconto | C20: =C18-C19 | O20: Quanto de VPL a origem criava só por ignorar o risco do projeto.
A21: TIR | C21: =IRR(C11:M11) | O21: Comparar com o WACC, não com a Selic.
A22: TIR − WACC | C22: =C21-'2. Inputs'!$C$81 | O22: O spread que sobra depois do custo de capital.
A23: Payback simples | C23: =IF(COUNTIF('5. Fluxo de Caixa'!C29:'5. Fluxo de Caixa'!M29,"<0")=0,0,IF(COUNTIF('5. Fluxo de Caixa'!C29:'5. Fluxo de Caixa'!M29,"<0")>=11,"não paga no horizonte",COUNTIF('5. Fluxo de Caixa'!C29:'5. Fluxo de Caixa'!M29,"<0")-1+ABS(INDEX('5. Fluxo de Caixa'!C29:'5. Fluxo de Caixa'!M29,COUNTIF('5. Fluxo de Caixa'!C29:'5. Fluxo de Caixa'!M29,"<0")))/INDEX(C11:M11,COUNTIF('5. Fluxo de Caixa'!C29:'5. Fluxo de Caixa'!M29,"<0")+1))) | O23: Na origem estava DIGITADO como texto ("2,5 anos"), não calculado.
A24: Payback descontado | C24: =IF(COUNTIF(C14:M14,"<0")=0,0,IF(COUNTIF(C14:M14,"<0")>=11,"não paga no horizonte",COUNTIF(C14:M14,"<0")-1+ABS(INDEX(C14:M14,COUNTIF(C14:M14,"<0")))/INDEX(C13:M13,COUNTIF(C14:M14,"<0")+1))) | O24: Descontado ao WACC.
A25: Índice de lucratividade | C25: =SUM(D13:M13)/ABS(C11) | O25: VP dos fluxos dos anos 1–10 sobre o desembolso do ano 0.
A27: C. VALOR TERMINAL — o que a origem não tinha
A28: Valor contábil líquido do imobilizado no ano 10 | B28: R$ | C28: ='3. Depreciacao'!M33 | O28: A planta continua existindo no fim do horizonte. A origem descartava esse valor.
A29: VP do valor residual do imobilizado | B29: R$ | C29: =C28*M12
A30: VPL com valor residual (visão de liquidação) | B30: R$ | C30: =C18+C29
A31: Perpetuidade a partir do FCL do ano 10 | B31: R$ | C31: =IFERROR((M11-'5. Fluxo de Caixa'!M27)*(1+'2. Inputs'!$C$83)/('2. Inputs'!$C$81-'2. Inputs'!$C$83),0) | O31: Cálculo: FCL ano 10 (líquido da liberação do giro) x (1+g) / (WACC − g).
A32: VP da perpetuidade | B32: R$ | C32: =C31*M12
A33: VPL com perpetuidade (visão de continuidade) | B33: R$ | C33: =C18+C32
A34: As três visões não se somam: escolha uma. Liquidação e continuidade são hipóteses alternativas sobre o que acontece no ano 11.
A36: D. PONTE DE VPL — DA ORIGEM AO MODELO
A37: VPL da origem | B37: R$ | C37: 66467823 | O37: Origem: 22.2 Fluxo de Caixa!J36, descontado à Selic de 12,25%.
A38: (1) Efeito de reconstruir o fluxo de caixa | B38: R$ | C38: =C19-C37 | O38: Volume = produzido; comissão de 3% virou despesa; CAPEX de 2028 e 2030 corrigidos; depreciação corrigida; capital de giro reconstruído. Mesma taxa de 12,25%.
A39: (2) Efeito de trocar a Selic pelo WACC | B39: R$ | C39: =C18-C19 | O39: O gap 4 do projeto, isolado.
A40: VPL do modelo @ WACC | B40: R$ | C40: =C37+C38+C39
A41: Check: bate com o VPL @ WACC? | C41: =IF(ABS(C40-C18)<1,"OK","ERRO")

Sheet 7. Cenarios e Sensibilidade
A1: CENÁRIOS, SENSIBILIDADE E PONTO DE EQUILÍBRIO
A2: A origem não tinha cenário, tabela de sensibilidade nem leitura de risco. O cálculo fica na aba 8; aqui só o resultado. Troque o cenário ativo na aba 2. Inputs, célula C5.
A6: A. OS TRÊS CENÁRIOS
A7: Métrica | B7: Pessimista | C7: Base | D7: Otimista | E7: Amplitude
A8: Δ volume | B8: ='8. Motor de Cenarios'!C7 | C8: ='8. Motor de Cenarios'!C8 | D8: ='8. Motor de Cenarios'!C9 | E8: =D8-B8
A9: Δ margem-alvo (p.p.) | B9: ='8. Motor de Cenarios'!D7 | C9: ='8. Motor de Cenarios'!D8 | D9: ='8. Motor de Cenarios'!D9 | E9: =D9-B9
A10: Δ custo variável unitário | B10: ='8. Motor de Cenarios'!E7 | C10: ='8. Motor de Cenarios'!E8 | D10: ='8. Motor de Cenarios'!E9 | E10: =D10-B10
A11: Contingência (% do CAPEX/ano) | B11: ='8. Motor de Cenarios'!F7 | C11: ='8. Motor de Cenarios'!F8 | D11: ='8. Motor de Cenarios'!F9 | E11: =D11-B11
A12: Participação do Sudeste | B12: ='8. Motor de Cenarios'!G7 | C12: ='8. Motor de Cenarios'!G8 | D12: ='8. Motor de Cenarios'!G9 | E12: =D12-B12
A13: EBITDA ano 1 | B13: ='8. Motor de Cenarios'!J7 | C13: ='8. Motor de Cenarios'!J8 | D13: ='8. Motor de Cenarios'!J9 | E13: =D13-B13
A14: Margem EBITDA ano 1 | B14: ='8. Motor de Cenarios'!K7 | C14: ='8. Motor de Cenarios'!K8 | D14: ='8. Motor de Cenarios'!K9 | E14: =D14-B14
A15: EBITDA ano 10 | B15: ='8. Motor de Cenarios'!L7 | C15: ='8. Motor de Cenarios'!L8 | D15: ='8. Motor de Cenarios'!L9 | E15: =D15-B15
A16: VPL @ WACC | B16: ='8. Motor de Cenarios'!H7 | C16: ='8. Motor de Cenarios'!H8 | D16: ='8. Motor de Cenarios'!H9 | E16: =D16-B16
A17: TIR | B17: ='8. Motor de Cenarios'!I7 | C17: ='8. Motor de Cenarios'!I8 | D17: ='8. Motor de Cenarios'!I9 | E17: =D17-B17
A18: Payback descontado (anos) | B18: ='8. Motor de Cenarios'!M7 | C18: ='8. Motor de Cenarios'!M8 | D18: ='8. Motor de Cenarios'!M9 | E18: =D18-B18
A20: Leitura
A21: • O VPL vai de R$ 25 mi a R$ 52 mi entre o pessimista e o otimista. Em nenhum dos três o projeto destrói valor: a TIR nunca cai abaixo de 37%, contra um WACC de 18%.
A22: • A alavanca que mais move o resultado é a margem-alvo, não o volume — e a margem-alvo é a premissa com menos base no caso (sobe 2 p.p. ao ano até 43%, sem estudo de preço).
A23: • No modo 1 de precificação (custo + markup, a lógica da origem), custo mais alto gera VPL mais alto, porque o preço sobe junto. É o comportamento do modelo, não do negócio: mude para o modo 2 na aba 2. Inputs para testar preço de mercado fixo.
A24: • O mix regional quase não move o resultado: o frete é 0,4% do custo e 80% do volume já está no Sudeste. Vale manter a alavanca, mas ela não é onde o risco mora.
A26: B. TORNADO — o que mais move o VPL
A27: Alavanca | B27: Cenário baixo | C27: VPL baixo | D27: Cenário alto | E27: VPL alto | F27: Amplitude | G27: % do VPL base
A28: Volume | B28: ='8. Motor de Cenarios'!B10 | C28: ='8. Motor de Cenarios'!H10 | D28: ='8. Motor de Cenarios'!B11 | E28: ='8. Motor de Cenarios'!H11 | F28: =ABS(E28-C28) | G28: =F28/'8. Motor de Cenarios'!$H$8
A29: Margem-alvo | B29: ='8. Motor de Cenarios'!B12 | C29: ='8. Motor de Cenarios'!H12 | D29: ='8. Motor de Cenarios'!B13 | E29: ='8. Motor de Cenarios'!H13 | F29: =ABS(E29-C29) | G29: =F29/'8. Motor de Cenarios'!$H$8
A30: Custo variável unitário | B30: ='8. Motor de Cenarios'!B14 | C30: ='8. Motor de Cenarios'!H14 | D30: ='8. Motor de Cenarios'!B15 | E30: ='8. Motor de Cenarios'!H15 | F30: =ABS(E30-C30) | G30: =F30/'8. Motor de Cenarios'!$H$8
A31: Contingência | B31: ='8. Motor de Cenarios'!B16 | C31: ='8. Motor de Cenarios'!H16 | D31: ='8. Motor de Cenarios'!B17 | E31: ='8. Motor de Cenarios'!H17 | F31: =ABS(E31-C31) | G31: =F31/'8. Motor de Cenarios'!$H$8
A32: Mix — participação do Sudeste | B32: ='8. Motor de Cenarios'!B18 | C32: ='8. Motor de Cenarios'!H18 | D32: ='8. Motor de Cenarios'!B19 | E32: ='8. Motor de Cenarios'!H19 | F32: =ABS(E32-C32) | G32: =F32/'8. Motor de Cenarios'!$H$8
A34: C. SENSIBILIDADE DO VPL AO CUSTO DE CAPITAL
A35: O fluxo de caixa não depende da taxa: esta linha é exata.
A36: Taxa de desconto | B36: 0.1225 | C36: 0.14 | D36: 0.16 | E36: 0.18 | F36: 0.2 | G36: 0.22 | H36: 0.24
A37: VPL sem valor terminal | B37: =SUMPRODUCT('5. Fluxo de Caixa'!$C$28:$M$28,1/(1+B$36)^'5. Fluxo de Caixa'!$C$7:$M$7) | C37: =SUMPRODUCT('5. Fluxo de Caixa'!$C$28:$M$28,1/(1+C$36)^'5. Fluxo de Caixa'!$C$7:$M$7) | D37: =SUMPRODUCT('5. Fluxo de Caixa'!$C$28:$M$28,1/(1+D$36)^'5. Fluxo de Caixa'!$C$7:$M$7) | E37: =SUMPRODUCT('5. Fluxo de Caixa'!$C$28:$M$28,1/(1+E$36)^'5. Fluxo de Caixa'!$C$7:$M$7) | F37: =SUMPRODUCT('5. Fluxo de Caixa'!$C$28:$M$28,1/(1+F$36)^'5. Fluxo de Caixa'!$C$7:$M$7) | G37: =SUMPRODUCT('5. Fluxo de Caixa'!$C$28:$M$28,1/(1+G$36)^'5. Fluxo de Caixa'!$C$7:$M$7) | H37: =SUMPRODUCT('5. Fluxo de Caixa'!$C$28:$M$28,1/(1+H$36)^'5. Fluxo de Caixa'!$C$7:$M$7)
A38: VPL ao WACC do modelo | B38: ='6. Valuation'!C18
A40: D. VPL COM PERPETUIDADE — taxa de desconto x crescimento na perpetuidade
A41: VPL (R$) | B41: 0 | C41: 0.01 | D41: 0.02 | E41: 0.03 | F41: 0.04
A42: 0.1225 | B42: =IF($A42<=B$41,"n/a",SUMPRODUCT('5. Fluxo de Caixa'!$C$28:$M$28,1/(1+$A42)^'5. Fluxo de Caixa'!$C$7:$M$7)+('5. Fluxo de Caixa'!$M$28-'5. Fluxo de Caixa'!$M$27)*(1+B$41)/($A42-B$41)/(1+$A42)^10) | C42: =IF($A42<=C$41,"n/a",SUMPRODUCT('5. Fluxo de Caixa'!$C$28:$M$28,1/(1+$A42)^'5. Fluxo de Caixa'!$C$7:$M$7)+('5. Fluxo de Caixa'!$M$28-'5. Fluxo de Caixa'!$M$27)*(1+C$41)/($A42-C$41)/(1+$A42)^10) | D42: =IF($A42<=D$41,"n/a",SUMPRODUCT('5. Fluxo de Caixa'!$C$28:$M$28,1/(1+$A42)^'5. Fluxo de Caixa'!$C$7:$M$7)+('5. Fluxo de Caixa'!$M$28-'5. Fluxo de Caixa'!$M$27)*(1+D$41)/($A42-D$41)/(1+$A42)^10) | E42: =IF($A42<=E$41,"n/a",SUMPRODUCT('5. Fluxo de Caixa'!$C$28:$M$28,1/(1+$A42)^'5. Fluxo de Caixa'!$C$7:$M$7)+('5. Fluxo de Caixa'!$M$28-'5. Fluxo de Caixa'!$M$27)*(1+E$41)/($A42-E$41)/(1+$A42)^10) | F42: =IF($A42<=F$41,"n/a",SUMPRODUCT('5. Fluxo de Caixa'!$C$28:$M$28,1/(1+$A42)^'5. Fluxo de Caixa'!$C$7:$M$7)+('5. Fluxo de Caixa'!$M$28-'5. Fluxo de Caixa'!$M$27)*(1+F$41)/($A42-F$41)/(1+$A42)^10)
A43: 0.14 | B43: =IF($A43<=B$41,"n/a",SUMPRODUCT('5. Fluxo de Caixa'!$C$28:$M$28,1/(1+$A43)^'5. Fluxo de Caixa'!$C$7:$M$7)+('5. Fluxo de Caixa'!$M$28-'5. Fluxo de Caixa'!$M$27)*(1+B$41)/($A43-B$41)/(1+$A43)^10) | C43: =IF($A43<=C$41,"n/a",SUMPRODUCT('5. Fluxo de Caixa'!$C$28:$M$28,1/(1+$A43)^'5. Fluxo de Caixa'!$C$7:$M$7)+('5. Fluxo de Caixa'!$M$28-'5. Fluxo de Caixa'!$M$27)*(1+C$41)/($A43-C$41)/(1+$A43)^10) | D43: =IF($A43<=D$41,"n/a",SUMPRODUCT('5. Fluxo de Caixa'!$C$28:$M$28,1/(1+$A43)^'5. Fluxo de Caixa'!$C$7:$M$7)+('5. Fluxo de Caixa'!$M$28-'5. Fluxo de Caixa'!$M$27)*(1+D$41)/($A43-D$41)/(1+$A43)^10) | E43: =IF($A43<=E$41,"n/a",SUMPRODUCT('5. Fluxo de Caixa'!$C$28:$M$28,1/(1+$A43)^'5. Fluxo de Caixa'!$C$7:$M$7)+('5. Fluxo de Caixa'!$M$28-'5. Fluxo de Caixa'!$M$27)*(1+E$41)/($A43-E$41)/(1+$A43)^10) | F43: =IF($A43<=F$41,"n/a",SUMPRODUCT('5. Fluxo de Caixa'!$C$28:$M$28,1/(1+$A43)^'5. Fluxo de Caixa'!$C$7:$M$7)+('5. Fluxo de Caixa'!$M$28-'5. Fluxo de Caixa'!$M$27)*(1+F$41)/($A43-F$41)/(1+$A43)^10)
A44: 0.16 | B44: =IF($A44<=B$41,"n/a",SUMPRODUCT('5. Fluxo de Caixa'!$C$28:$M$28,1/(1+$A44)^'5. Fluxo de Caixa'!$C$7:$M$7)+('5. Fluxo de Caixa'!$M$28-'5. Fluxo de Caixa'!$M$27)*(1+B$41)/($A44-B$41)/(1+$A44)^10) | C44: =IF($A44<=C$41,"n/a",SUMPRODUCT('5. Fluxo de Caixa'!$C$28:$M$28,1/(1+$A44)^'5. Fluxo de Caixa'!$C$7:$M$7)+('5. Fluxo de Caixa'!$M$28-'5. Fluxo de Caixa'!$M$27)*(1+C$41)/($A44-C$41)/(1+$A44)^10) | D44: =IF($A44<=D$41,"n/a",SUMPRODUCT('5. Fluxo de Caixa'!$C$28:$M$28,1/(1+$A44)^'5. Fluxo de Caixa'!$C$7:$M$7)+('5. Fluxo de Caixa'!$M$28-'5. Fluxo de Caixa'!$M$27)*(1+D$41)/($A44-D$41)/(1+$A44)^10) | E44: =IF($A44<=E$41,"n/a",SUMPRODUCT('5. Fluxo de Caixa'!$C$28:$M$28,1/(1+$A44)^'5. Fluxo de Caixa'!$C$7:$M$7)+('5. Fluxo de Caixa'!$M$28-'5. Fluxo de Caixa'!$M$27)*(1+E$41)/($A44-E$41)/(1+$A44)^10) | F44: =IF($A44<=F$41,"n/a",SUMPRODUCT('5. Fluxo de Caixa'!$C$28:$M$28,1/(1+$A44)^'5. Fluxo de Caixa'!$C$7:$M$7)+('5. Fluxo de Caixa'!$M$28-'5. Fluxo de Caixa'!$M$27)*(1+F$41)/($A44-F$41)/(1+$A44)^10)
A45: 0.18 | B45: =IF($A45<=B$41,"n/a",SUMPRODUCT('5. Fluxo de Caixa'!$C$28:$M$28,1/(1+$A45)^'5. Fluxo de Caixa'!$C$7:$M$7)+('5. Fluxo de Caixa'!$M$28-'5. Fluxo de Caixa'!$M$27)*(1+B$41)/($A45-B$41)/(1+$A45)^10) | C45: =IF($A45<=C$41,"n/a",SUMPRODUCT('5. Fluxo de Caixa'!$C$28:$M$28,1/(1+$A45)^'5. Fluxo de Caixa'!$C$7:$M$7)+('5. Fluxo de Caixa'!$M$28-'5. Fluxo de Caixa'!$M$27)*(1+C$41)/($A45-C$41)/(1+$A45)^10) | D45: =IF($A45<=D$41,"n/a",SUMPRODUCT('5. Fluxo de Caixa'!$C$28:$M$28,1/(1+$A45)^'5. Fluxo de Caixa'!$C$7:$M$7)+('5. Fluxo de Caixa'!$M$28-'5. Fluxo de Caixa'!$M$27)*(1+D$41)/($A45-D$41)/(1+$A45)^10) | E45: =IF($A45<=E$41,"n/a",SUMPRODUCT('5. Fluxo de Caixa'!$C$28:$M$28,1/(1+$A45)^'5. Fluxo de Caixa'!$C$7:$M$7)+('5. Fluxo de Caixa'!$M$28-'5. Fluxo de Caixa'!$M$27)*(1+E$41)/($A45-E$41)/(1+$A45)^10) | F45: =IF($A45<=F$41,"n/a",SUMPRODUCT('5. Fluxo de Caixa'!$C$28:$M$28,1/(1+$A45)^'5. Fluxo de Caixa'!$C$7:$M$7)+('5. Fluxo de Caixa'!$M$28-'5. Fluxo de Caixa'!$M$27)*(1+F$41)/($A45-F$41)/(1+$A45)^10)
